[2025-05-27T13:22:15.712+0000] {taskinstance.py:1956} INFO - Dependencies all met for dep_context=non-requeueable deps ti=<TaskInstance: postgres_to_mysql.replicate_pg_to_mysql scheduled__2025-05-27T12:00:00+00:00 [queued]>
[2025-05-27T13:22:15.724+0000] {taskinstance.py:1956} INFO - Dependencies all met for dep_context=requeueable deps ti=<TaskInstance: postgres_to_mysql.replicate_pg_to_mysql scheduled__2025-05-27T12:00:00+00:00 [queued]>
[2025-05-27T13:22:15.724+0000] {taskinstance.py:2170} INFO - Starting attempt 1 of 1
[2025-05-27T13:22:15.751+0000] {taskinstance.py:2191} INFO - Executing <Task(PythonOperator): replicate_pg_to_mysql> on 2025-05-27 12:00:00+00:00
[2025-05-27T13:22:15.777+0000] {standard_task_runner.py:60} INFO - Started process 218 to run task
[2025-05-27T13:22:15.782+0000] {standard_task_runner.py:87} INFO - Running: ['airflow', 'tasks', 'run', '***_to_mysql', 'replicate_pg_to_mysql', 'scheduled__2025-05-27T12:00:00+00:00', '--job-id', '2', '--raw', '--subdir', 'DAGS_FOLDER/***_to_mysql.py', '--cfg-path', '/tmp/tmpcmrgk54p']
[2025-05-27T13:22:15.788+0000] {standard_task_runner.py:88} INFO - Job 2: Subtask replicate_pg_to_mysql
[2025-05-27T13:22:15.845+0000] {logging_mixin.py:188} WARNING - /home/airflow/.local/lib/python3.8/site-packages/airflow/settings.py:194 DeprecationWarning: The sql_alchemy_conn option in [core] has been moved to the sql_alchemy_conn option in [database] - the old setting has been used, but please update your config.
[2025-05-27T13:22:15.962+0000] {task_command.py:423} INFO - Running <TaskInstance: postgres_to_mysql.replicate_pg_to_mysql scheduled__2025-05-27T12:00:00+00:00 [running]> on host e0d48ac59603
[2025-05-27T13:22:16.281+0000] {taskinstance.py:2480} INFO - Exporting env vars: AIRFLOW_CTX_DAG_OWNER='airflow' AIRFLOW_CTX_DAG_ID='***_to_mysql' AIRFLOW_CTX_TASK_ID='replicate_pg_to_mysql' AIRFLOW_CTX_EXECUTION_DATE='2025-05-27T12:00:00+00:00' AIRFLOW_CTX_TRY_NUMBER='1' AIRFLOW_CTX_DAG_RUN_ID='scheduled__2025-05-27T12:00:00+00:00'
[2025-05-27T13:22:16.289+0000] {taskinstance.py:2698} ERROR - Task failed with exception
Traceback (most recent call last):
  File "/home/airflow/.local/lib/python3.8/site-packages/airflow/models/taskinstance.py", line 433, in _execute_task
    result = execute_callable(context=context, **execute_callable_kwargs)
  File "/home/airflow/.local/lib/python3.8/site-packages/airflow/operators/python.py", line 199, in execute
    return_value = self.execute_callable()
  File "/home/airflow/.local/lib/python3.8/site-packages/airflow/operators/python.py", line 216, in execute_callable
    return self.python_callable(*self.op_args, **self.op_kwargs)
  File "/opt/airflow/dags/postgres_to_mysql.py", line 9, in pg_to_mysql
    mysql = sqlalchemy.create_engine("mysql+pymysql://root:root@mysql:3306/source_db")
  File "<string>", line 2, in create_engine
  File "/home/airflow/.local/lib/python3.8/site-packages/sqlalchemy/util/deprecations.py", line 375, in warned
    return fn(*args, **kwargs)
  File "/home/airflow/.local/lib/python3.8/site-packages/sqlalchemy/engine/create.py", line 544, in create_engine
    dbapi = dialect_cls.dbapi(**dbapi_args)
  File "/home/airflow/.local/lib/python3.8/site-packages/sqlalchemy/dialects/mysql/pymysql.py", line 80, in dbapi
    return __import__("pymysql")
ModuleNotFoundError: No module named 'pymysql'
[2025-05-27T13:22:16.322+0000] {taskinstance.py:1138} INFO - Marking task as FAILED. dag_id=***_to_mysql, task_id=replicate_pg_to_mysql, execution_date=20250527T120000, start_date=20250527T132215, end_date=20250527T132216
[2025-05-27T13:22:17.266+0000] {standard_task_runner.py:107} ERROR - Failed to execute job 2 for task replicate_pg_to_mysql (No module named 'pymysql'; 218)
[2025-05-27T13:22:17.325+0000] {local_task_job_runner.py:234} INFO - Task exited with return code 1
[2025-05-27T13:22:17.388+0000] {taskinstance.py:3280} INFO - 0 downstream tasks scheduled from follow-on schedule check
[2025-05-27T13:27:17.422+0000] {taskinstance.py:1956} INFO - Dependencies all met for dep_context=non-requeueable deps ti=<TaskInstance: postgres_to_mysql.replicate_pg_to_mysql scheduled__2025-05-27T12:00:00+00:00 [queued]>
[2025-05-27T13:27:17.467+0000] {taskinstance.py:1956} INFO - Dependencies all met for dep_context=requeueable deps ti=<TaskInstance: postgres_to_mysql.replicate_pg_to_mysql scheduled__2025-05-27T12:00:00+00:00 [queued]>
[2025-05-27T13:27:17.470+0000] {taskinstance.py:2170} INFO - Starting attempt 1 of 1
[2025-05-27T13:27:17.512+0000] {taskinstance.py:2191} INFO - Executing <Task(PythonOperator): replicate_pg_to_mysql> on 2025-05-27 12:00:00+00:00
[2025-05-27T13:27:17.524+0000] {standard_task_runner.py:60} INFO - Started process 239 to run task
[2025-05-27T13:27:17.527+0000] {standard_task_runner.py:87} INFO - Running: ['airflow', 'tasks', 'run', '***_to_mysql', 'replicate_pg_to_mysql', 'scheduled__2025-05-27T12:00:00+00:00', '--job-id', '2', '--raw', '--subdir', 'DAGS_FOLDER/***_to_mysql.py', '--cfg-path', '/tmp/tmpq23accn2']
[2025-05-27T13:27:17.532+0000] {standard_task_runner.py:88} INFO - Job 2: Subtask replicate_pg_to_mysql
[2025-05-27T13:27:17.566+0000] {logging_mixin.py:188} WARNING - /home/airflow/.local/lib/python3.8/site-packages/airflow/settings.py:194 DeprecationWarning: The sql_alchemy_conn option in [core] has been moved to the sql_alchemy_conn option in [database] - the old setting has been used, but please update your config.
[2025-05-27T13:27:17.643+0000] {task_command.py:423} INFO - Running <TaskInstance: postgres_to_mysql.replicate_pg_to_mysql scheduled__2025-05-27T12:00:00+00:00 [running]> on host 787ff935b26f
[2025-05-27T13:27:17.799+0000] {taskinstance.py:2480} INFO - Exporting env vars: AIRFLOW_CTX_DAG_OWNER='airflow' AIRFLOW_CTX_DAG_ID='***_to_mysql' AIRFLOW_CTX_TASK_ID='replicate_pg_to_mysql' AIRFLOW_CTX_EXECUTION_DATE='2025-05-27T12:00:00+00:00' AIRFLOW_CTX_TRY_NUMBER='1' AIRFLOW_CTX_DAG_RUN_ID='scheduled__2025-05-27T12:00:00+00:00'
[2025-05-27T13:27:18.908+0000] {taskinstance.py:2698} ERROR - Task failed with exception
Traceback (most recent call last):
  File "/home/airflow/.local/lib/python3.8/site-packages/sqlalchemy/engine/base.py", line 1910, in _execute_context
    self.dialect.do_execute(
  File "/home/airflow/.local/lib/python3.8/site-packages/sqlalchemy/engine/default.py", line 736, in do_execute
    cursor.execute(statement, parameters)
psycopg2.errors.UndefinedTable: relation "customers" does not exist
LINE 1: SELECT * FROM customers
                      ^


The above exception was the direct cause of the following exception:

Traceback (most recent call last):
  File "/home/airflow/.local/lib/python3.8/site-packages/airflow/models/taskinstance.py", line 433, in _execute_task
    result = execute_callable(context=context, **execute_callable_kwargs)
  File "/home/airflow/.local/lib/python3.8/site-packages/airflow/operators/python.py", line 199, in execute
    return_value = self.execute_callable()
  File "/home/airflow/.local/lib/python3.8/site-packages/airflow/operators/python.py", line 216, in execute_callable
    return self.python_callable(*self.op_args, **self.op_kwargs)
  File "/opt/airflow/dags/postgres_to_mysql.py", line 10, in pg_to_mysql
    df = pd.read_sql("SELECT * FROM customers", con=pg)
  File "/home/airflow/.local/lib/python3.8/site-packages/pandas/io/sql.py", line 663, in read_sql
    return pandas_sql.read_query(
  File "/home/airflow/.local/lib/python3.8/site-packages/pandas/io/sql.py", line 1738, in read_query
    result = self.execute(sql, params)
  File "/home/airflow/.local/lib/python3.8/site-packages/pandas/io/sql.py", line 1562, in execute
    return self.con.exec_driver_sql(sql, *args)
  File "/home/airflow/.local/lib/python3.8/site-packages/sqlalchemy/engine/base.py", line 1770, in exec_driver_sql
    return self._exec_driver_sql(
  File "/home/airflow/.local/lib/python3.8/site-packages/sqlalchemy/engine/base.py", line 1674, in _exec_driver_sql
    ret = self._execute_context(
  File "/home/airflow/.local/lib/python3.8/site-packages/sqlalchemy/engine/base.py", line 1953, in _execute_context
    self._handle_dbapi_exception(
  File "/home/airflow/.local/lib/python3.8/site-packages/sqlalchemy/engine/base.py", line 2134, in _handle_dbapi_exception
    util.raise_(
  File "/home/airflow/.local/lib/python3.8/site-packages/sqlalchemy/util/compat.py", line 211, in raise_
    raise exception
  File "/home/airflow/.local/lib/python3.8/site-packages/sqlalchemy/engine/base.py", line 1910, in _execute_context
    self.dialect.do_execute(
  File "/home/airflow/.local/lib/python3.8/site-packages/sqlalchemy/engine/default.py", line 736, in do_execute
    cursor.execute(statement, parameters)
sqlalchemy.exc.ProgrammingError: (psycopg2.errors.UndefinedTable) relation "customers" does not exist
LINE 1: SELECT * FROM customers
                      ^

[SQL: SELECT * FROM customers]
(Background on this error at: https://sqlalche.me/e/14/f405)
[2025-05-27T13:27:18.930+0000] {taskinstance.py:1138} INFO - Marking task as FAILED. dag_id=***_to_mysql, task_id=replicate_pg_to_mysql, execution_date=20250527T120000, start_date=20250527T132717, end_date=20250527T132718
[2025-05-27T13:27:18.958+0000] {standard_task_runner.py:107} ERROR - Failed to execute job 2 for task replicate_pg_to_mysql ((psycopg2.errors.UndefinedTable) relation "customers" does not exist
LINE 1: SELECT * FROM customers
                      ^

[SQL: SELECT * FROM customers]
(Background on this error at: https://sqlalche.me/e/14/f405); 239)
[2025-05-27T13:27:19.053+0000] {local_task_job_runner.py:234} INFO - Task exited with return code 1
[2025-05-27T13:27:19.137+0000] {taskinstance.py:3280} INFO - 0 downstream tasks scheduled from follow-on schedule check
