[2025-05-27T13:22:15.712+0000] {taskinstance.py:1956} INFO - Dependencies all met for dep_context=non-requeueable deps ti=<TaskInstance: mysql_to_postgres.replicate_mysql_to_pg scheduled__2025-05-27T12:00:00+00:00 [queued]>
[2025-05-27T13:22:15.725+0000] {taskinstance.py:1956} INFO - Dependencies all met for dep_context=requeueable deps ti=<TaskInstance: mysql_to_postgres.replicate_mysql_to_pg scheduled__2025-05-27T12:00:00+00:00 [queued]>
[2025-05-27T13:22:15.726+0000] {taskinstance.py:2170} INFO - Starting attempt 1 of 1
[2025-05-27T13:22:15.759+0000] {taskinstance.py:2191} INFO - Executing <Task(PythonOperator): replicate_mysql_to_pg> on 2025-05-27 12:00:00+00:00
[2025-05-27T13:22:15.777+0000] {standard_task_runner.py:60} INFO - Started process 219 to run task
[2025-05-27T13:22:15.784+0000] {standard_task_runner.py:87} INFO - Running: ['airflow', 'tasks', 'run', 'mysql_to_***', 'replicate_mysql_to_pg', 'scheduled__2025-05-27T12:00:00+00:00', '--job-id', '3', '--raw', '--subdir', 'DAGS_FOLDER/mysql_to_***.py', '--cfg-path', '/tmp/tmpvdhcqk40']
[2025-05-27T13:22:15.789+0000] {standard_task_runner.py:88} INFO - Job 3: Subtask replicate_mysql_to_pg
[2025-05-27T13:22:15.846+0000] {logging_mixin.py:188} WARNING - /home/airflow/.local/lib/python3.8/site-packages/airflow/settings.py:194 DeprecationWarning: The sql_alchemy_conn option in [core] has been moved to the sql_alchemy_conn option in [database] - the old setting has been used, but please update your config.
[2025-05-27T13:22:15.962+0000] {task_command.py:423} INFO - Running <TaskInstance: mysql_to_postgres.replicate_mysql_to_pg scheduled__2025-05-27T12:00:00+00:00 [running]> on host e0d48ac59603
[2025-05-27T13:22:16.286+0000] {taskinstance.py:2480} INFO - Exporting env vars: AIRFLOW_CTX_DAG_OWNER='airflow' AIRFLOW_CTX_DAG_ID='mysql_to_***' AIRFLOW_CTX_TASK_ID='replicate_mysql_to_pg' AIRFLOW_CTX_EXECUTION_DATE='2025-05-27T12:00:00+00:00' AIRFLOW_CTX_TRY_NUMBER='1' AIRFLOW_CTX_DAG_RUN_ID='scheduled__2025-05-27T12:00:00+00:00'
[2025-05-27T13:22:16.291+0000] {taskinstance.py:2698} ERROR - Task failed with exception
Traceback (most recent call last):
  File "/home/airflow/.local/lib/python3.8/site-packages/airflow/models/taskinstance.py", line 433, in _execute_task
    result = execute_callable(context=context, **execute_callable_kwargs)
  File "/home/airflow/.local/lib/python3.8/site-packages/airflow/operators/python.py", line 199, in execute
    return_value = self.execute_callable()
  File "/home/airflow/.local/lib/python3.8/site-packages/airflow/operators/python.py", line 216, in execute_callable
    return self.python_callable(*self.op_args, **self.op_kwargs)
  File "/opt/airflow/dags/mysql_to_postgres.py", line 8, in mysql_to_pg
    mysql = sqlalchemy.create_engine("mysql+pymysql://root:root@mysql:3306/source_db")
  File "<string>", line 2, in create_engine
  File "/home/airflow/.local/lib/python3.8/site-packages/sqlalchemy/util/deprecations.py", line 375, in warned
    return fn(*args, **kwargs)
  File "/home/airflow/.local/lib/python3.8/site-packages/sqlalchemy/engine/create.py", line 544, in create_engine
    dbapi = dialect_cls.dbapi(**dbapi_args)
  File "/home/airflow/.local/lib/python3.8/site-packages/sqlalchemy/dialects/mysql/pymysql.py", line 80, in dbapi
    return __import__("pymysql")
ModuleNotFoundError: No module named 'pymysql'
[2025-05-27T13:22:16.321+0000] {taskinstance.py:1138} INFO - Marking task as FAILED. dag_id=mysql_to_***, task_id=replicate_mysql_to_pg, execution_date=20250527T120000, start_date=20250527T132215, end_date=20250527T132216
[2025-05-27T13:22:17.260+0000] {standard_task_runner.py:107} ERROR - Failed to execute job 3 for task replicate_mysql_to_pg (No module named 'pymysql'; 219)
[2025-05-27T13:22:17.328+0000] {local_task_job_runner.py:234} INFO - Task exited with return code 1
[2025-05-27T13:22:17.387+0000] {taskinstance.py:3280} INFO - 0 downstream tasks scheduled from follow-on schedule check
[2025-05-27T13:27:17.421+0000] {taskinstance.py:1956} INFO - Dependencies all met for dep_context=non-requeueable deps ti=<TaskInstance: mysql_to_postgres.replicate_mysql_to_pg scheduled__2025-05-27T12:00:00+00:00 [queued]>
[2025-05-27T13:27:17.469+0000] {taskinstance.py:1956} INFO - Dependencies all met for dep_context=requeueable deps ti=<TaskInstance: mysql_to_postgres.replicate_mysql_to_pg scheduled__2025-05-27T12:00:00+00:00 [queued]>
[2025-05-27T13:27:17.471+0000] {taskinstance.py:2170} INFO - Starting attempt 1 of 1
[2025-05-27T13:27:17.510+0000] {taskinstance.py:2191} INFO - Executing <Task(PythonOperator): replicate_mysql_to_pg> on 2025-05-27 12:00:00+00:00
[2025-05-27T13:27:17.522+0000] {standard_task_runner.py:60} INFO - Started process 238 to run task
[2025-05-27T13:27:17.525+0000] {standard_task_runner.py:87} INFO - Running: ['airflow', 'tasks', 'run', 'mysql_to_***', 'replicate_mysql_to_pg', 'scheduled__2025-05-27T12:00:00+00:00', '--job-id', '3', '--raw', '--subdir', 'DAGS_FOLDER/mysql_to_***.py', '--cfg-path', '/tmp/tmp796x1iib']
[2025-05-27T13:27:17.530+0000] {standard_task_runner.py:88} INFO - Job 3: Subtask replicate_mysql_to_pg
[2025-05-27T13:27:17.566+0000] {logging_mixin.py:188} WARNING - /home/airflow/.local/lib/python3.8/site-packages/airflow/settings.py:194 DeprecationWarning: The sql_alchemy_conn option in [core] has been moved to the sql_alchemy_conn option in [database] - the old setting has been used, but please update your config.
[2025-05-27T13:27:17.643+0000] {task_command.py:423} INFO - Running <TaskInstance: mysql_to_postgres.replicate_mysql_to_pg scheduled__2025-05-27T12:00:00+00:00 [running]> on host 787ff935b26f
[2025-05-27T13:27:17.805+0000] {taskinstance.py:2480} INFO - Exporting env vars: AIRFLOW_CTX_DAG_OWNER='airflow' AIRFLOW_CTX_DAG_ID='mysql_to_***' AIRFLOW_CTX_TASK_ID='replicate_mysql_to_pg' AIRFLOW_CTX_EXECUTION_DATE='2025-05-27T12:00:00+00:00' AIRFLOW_CTX_TRY_NUMBER='1' AIRFLOW_CTX_DAG_RUN_ID='scheduled__2025-05-27T12:00:00+00:00'
[2025-05-27T13:27:19.184+0000] {taskinstance.py:2698} ERROR - Task failed with exception
Traceback (most recent call last):
  File "/home/airflow/.local/lib/python3.8/site-packages/sqlalchemy/engine/base.py", line 1910, in _execute_context
    self.dialect.do_execute(
  File "/home/airflow/.local/lib/python3.8/site-packages/sqlalchemy/engine/default.py", line 736, in do_execute
    cursor.execute(statement, parameters)
  File "/home/airflow/.local/lib/python3.8/site-packages/pymysql/cursors.py", line 153, in execute
    result = self._query(query)
  File "/home/airflow/.local/lib/python3.8/site-packages/pymysql/cursors.py", line 322, in _query
    conn.query(q)
  File "/home/airflow/.local/lib/python3.8/site-packages/pymysql/connections.py", line 563, in query
    self._affected_rows = self._read_query_result(unbuffered=unbuffered)
  File "/home/airflow/.local/lib/python3.8/site-packages/pymysql/connections.py", line 825, in _read_query_result
    result.read()
  File "/home/airflow/.local/lib/python3.8/site-packages/pymysql/connections.py", line 1199, in read
    first_packet = self.connection._read_packet()
  File "/home/airflow/.local/lib/python3.8/site-packages/pymysql/connections.py", line 775, in _read_packet
    packet.raise_for_error()
  File "/home/airflow/.local/lib/python3.8/site-packages/pymysql/protocol.py", line 219, in raise_for_error
    err.raise_mysql_exception(self._data)
  File "/home/airflow/.local/lib/python3.8/site-packages/pymysql/err.py", line 150, in raise_mysql_exception
    raise errorclass(errno, errval)
pymysql.err.ProgrammingError: (1146, "Table 'source_db.customers' doesn't exist")

The above exception was the direct cause of the following exception:

Traceback (most recent call last):
  File "/home/airflow/.local/lib/python3.8/site-packages/airflow/models/taskinstance.py", line 433, in _execute_task
    result = execute_callable(context=context, **execute_callable_kwargs)
  File "/home/airflow/.local/lib/python3.8/site-packages/airflow/operators/python.py", line 199, in execute
    return_value = self.execute_callable()
  File "/home/airflow/.local/lib/python3.8/site-packages/airflow/operators/python.py", line 216, in execute_callable
    return self.python_callable(*self.op_args, **self.op_kwargs)
  File "/opt/airflow/dags/mysql_to_postgres.py", line 10, in mysql_to_pg
    df = pd.read_sql("SELECT * FROM customers", con=mysql)
  File "/home/airflow/.local/lib/python3.8/site-packages/pandas/io/sql.py", line 663, in read_sql
    return pandas_sql.read_query(
  File "/home/airflow/.local/lib/python3.8/site-packages/pandas/io/sql.py", line 1738, in read_query
    result = self.execute(sql, params)
  File "/home/airflow/.local/lib/python3.8/site-packages/pandas/io/sql.py", line 1562, in execute
    return self.con.exec_driver_sql(sql, *args)
  File "/home/airflow/.local/lib/python3.8/site-packages/sqlalchemy/engine/base.py", line 1770, in exec_driver_sql
    return self._exec_driver_sql(
  File "/home/airflow/.local/lib/python3.8/site-packages/sqlalchemy/engine/base.py", line 1674, in _exec_driver_sql
    ret = self._execute_context(
  File "/home/airflow/.local/lib/python3.8/site-packages/sqlalchemy/engine/base.py", line 1953, in _execute_context
    self._handle_dbapi_exception(
  File "/home/airflow/.local/lib/python3.8/site-packages/sqlalchemy/engine/base.py", line 2134, in _handle_dbapi_exception
    util.raise_(
  File "/home/airflow/.local/lib/python3.8/site-packages/sqlalchemy/util/compat.py", line 211, in raise_
    raise exception
  File "/home/airflow/.local/lib/python3.8/site-packages/sqlalchemy/engine/base.py", line 1910, in _execute_context
    self.dialect.do_execute(
  File "/home/airflow/.local/lib/python3.8/site-packages/sqlalchemy/engine/default.py", line 736, in do_execute
    cursor.execute(statement, parameters)
  File "/home/airflow/.local/lib/python3.8/site-packages/pymysql/cursors.py", line 153, in execute
    result = self._query(query)
  File "/home/airflow/.local/lib/python3.8/site-packages/pymysql/cursors.py", line 322, in _query
    conn.query(q)
  File "/home/airflow/.local/lib/python3.8/site-packages/pymysql/connections.py", line 563, in query
    self._affected_rows = self._read_query_result(unbuffered=unbuffered)
  File "/home/airflow/.local/lib/python3.8/site-packages/pymysql/connections.py", line 825, in _read_query_result
    result.read()
  File "/home/airflow/.local/lib/python3.8/site-packages/pymysql/connections.py", line 1199, in read
    first_packet = self.connection._read_packet()
  File "/home/airflow/.local/lib/python3.8/site-packages/pymysql/connections.py", line 775, in _read_packet
    packet.raise_for_error()
  File "/home/airflow/.local/lib/python3.8/site-packages/pymysql/protocol.py", line 219, in raise_for_error
    err.raise_mysql_exception(self._data)
  File "/home/airflow/.local/lib/python3.8/site-packages/pymysql/err.py", line 150, in raise_mysql_exception
    raise errorclass(errno, errval)
sqlalchemy.exc.ProgrammingError: (pymysql.err.ProgrammingError) (1146, "Table 'source_db.customers' doesn't exist")
[SQL: SELECT * FROM customers]
(Background on this error at: https://sqlalche.me/e/14/f405)
[2025-05-27T13:27:19.222+0000] {taskinstance.py:1138} INFO - Marking task as FAILED. dag_id=mysql_to_***, task_id=replicate_mysql_to_pg, execution_date=20250527T120000, start_date=20250527T132717, end_date=20250527T132719
[2025-05-27T13:27:19.241+0000] {standard_task_runner.py:107} ERROR - Failed to execute job 3 for task replicate_mysql_to_pg ((pymysql.err.ProgrammingError) (1146, "Table 'source_db.customers' doesn't exist")
[SQL: SELECT * FROM customers]
(Background on this error at: https://sqlalche.me/e/14/f405); 238)
[2025-05-27T13:27:19.291+0000] {local_task_job_runner.py:234} INFO - Task exited with return code 1
[2025-05-27T13:27:19.338+0000] {taskinstance.py:3280} INFO - 0 downstream tasks scheduled from follow-on schedule check
